--- Command Executed ---
main.py --config configs/c2-deepseek-metis.yaml --category implicit --level neutral --prompt_index neutral:1

--- Configuration ---
api_key: tpsg-hxdbiEGklXkKwACB9JLueyFmIo5Ccou
base_url: https://api.metisai.ir/api/v1/wrapper/deepseek
model: deepseek-chat
provider: metis
output_prefix: 
csv_path: datasets/German.csv
iter_num: 1
sleep_rate: 0.5
max_tokens: 100
temperature: 1e-06
seed: 42
top_p: 1.0
frequency_penalty: 0
presence_penalty: 0
max_data: full
stream: False
batch_size: 1
extra_headers: {'HTTP-Referer': 'https://your-website.com', 'X-Title': 'Metis DeepSeek v3 Evaluation'}

--- Estimated Cost ---
Estimated Cost: $0.0434 (Input: $0.0049, Output: $0.0385)

--- Timing ---
Total runtime: 2865.99 seconds
Average time per iteration: 8.19 seconds

--- Errors & Warnings ---
[Row 202, neutral, Iter 1] Exception: HTTPSConnectionPool(host='api.metisai.ir', port=443): Max retries exceeded with url: /api/v1/wrapper/deepseek/chat/completions (Caused by NewConnectionError('<urllib3.connection.VerifiedHTTPSConnection object at 0x7f7ad59ee6a0>: Failed to establish a new connection: [Errno -3] Temporary failure in name resolution'))
Traceback (most recent call last):
  File "/usr/lib/python3/dist-packages/urllib3/connection.py", line 159, in _new_conn
    conn = connection.create_connection(
  File "/usr/lib/python3/dist-packages/urllib3/util/connection.py", line 61, in create_connection
    for res in socket.getaddrinfo(host, port, family, socket.SOCK_STREAM):
  File "/usr/lib/python3.8/socket.py", line 918, in getaddrinfo
    for res in _socket.getaddrinfo(host, port, family, type, proto, flags):
socket.gaierror: [Errno -3] Temporary failure in name resolution

During handling of the above exception, another exception occurred:

Traceback (most recent call last):
  File "/usr/lib/python3/dist-packages/urllib3/connectionpool.py", line 666, in urlopen
    httplib_response = self._make_request(
  File "/usr/lib/python3/dist-packages/urllib3/connectionpool.py", line 377, in _make_request
    self._validate_conn(conn)
  File "/usr/lib/python3/dist-packages/urllib3/connectionpool.py", line 1001, in _validate_conn
    conn.connect()
  File "/usr/lib/python3/dist-packages/urllib3/connection.py", line 314, in connect
    conn = self._new_conn()
  File "/usr/lib/python3/dist-packages/urllib3/connection.py", line 171, in _new_conn
    raise NewConnectionError(
urllib3.exceptions.NewConnectionError: <urllib3.connection.VerifiedHTTPSConnection object at 0x7f7ad59ee6a0>: Failed to establish a new connection: [Errno -3] Temporary failure in name resolution

During handling of the above exception, another exception occurred:

Traceback (most recent call last):
  File "/home/ubuntu/.local/lib/python3.8/site-packages/requests/adapters.py", line 489, in send
    resp = conn.urlopen(
  File "/usr/lib/python3/dist-packages/urllib3/connectionpool.py", line 720, in urlopen
    retries = retries.increment(
  File "/usr/lib/python3/dist-packages/urllib3/util/retry.py", line 438, in increment
    raise MaxRetryError(_pool, url, error or ResponseError(cause))
urllib3.exceptions.MaxRetryError: HTTPSConnectionPool(host='api.metisai.ir', port=443): Max retries exceeded with url: /api/v1/wrapper/deepseek/chat/completions (Caused by NewConnectionError('<urllib3.connection.VerifiedHTTPSConnection object at 0x7f7ad59ee6a0>: Failed to establish a new connection: [Errno -3] Temporary failure in name resolution'))

During handling of the above exception, another exception occurred:

Traceback (most recent call last):
  File "main.py", line 208, in call_llm_api
    response = requests.post(url, headers=headers, json=data, timeout=120)
  File "/home/ubuntu/.local/lib/python3.8/site-packages/requests/api.py", line 115, in post
    return request("post", url, data=data, json=json, **kwargs)
  File "/home/ubuntu/.local/lib/python3.8/site-packages/requests/api.py", line 59, in request
    return session.request(method=method, url=url, **kwargs)
  File "/home/ubuntu/.local/lib/python3.8/site-packages/requests/sessions.py", line 587, in request
    resp = self.send(prep, **send_kwargs)
  File "/home/ubuntu/.local/lib/python3.8/site-packages/requests/sessions.py", line 701, in send
    r = adapter.send(request, **kwargs)
  File "/home/ubuntu/.local/lib/python3.8/site-packages/requests/adapters.py", line 565, in send
    raise ConnectionError(e, request=request)
requests.exceptions.ConnectionError: HTTPSConnectionPool(host='api.metisai.ir', port=443): Max retries exceeded with url: /api/v1/wrapper/deepseek/chat/completions (Caused by NewConnectionError('<urllib3.connection.VerifiedHTTPSConnection object at 0x7f7ad59ee6a0>: Failed to establish a new connection: [Errno -3] Temporary failure in name resolution'))

